Workbook

Sheet Thông Tin Chiến Sĩ
A1: MÃ QUÂN NHÂN | B1: HỌ VÀ TÊN | C1: MÃ ĐƠN VỊ (Không nhập) | D1: ĐƠN VỊ | E1: CHỨC VỤ | F1: MÃ CẤP BẬC (Không nhập) | G1: CẤP BẬC | H1: NGÀY SINH | I1: GIỚI TÍNH | J1: CCCD | K1: QUÊ QUÁN (XÃ, TỈNH) | L1: ĐỊA CHỈ HIỆN TẠI | Q1: DÂN TỘC | R1: ĐỐI TƯỢNG | S1: TÔN GIÁO | T1: MÃ TÌNH TRẠNG HÔN NHÂN (Không nhập) | U1: TÌNH TRẠNG HÔN NHÂN | V1: TRÌNH ĐỘ HỌC VẤN | W1: CHUYÊN MÔN | X1: CHÌNH ĐỘ CHÍNH TRỊ | Y1: NHÓM MÁU | Z1: LOẠI SỨC KHỎE | AA1: CHIỀU CAO | AB1: CÂN NẶNG | AC1: HUYẾT ÁP | AD1: NGÀY NHẬP NGŨ | AE1: NGÀY VÀO ĐẢNG | AF1: NGÀY VÀO ĐOÀN | AG1: LINK ẢNH ĐẠI DIỆN (mã quân nhân.jpg) VD: 123456.jpg
L2: MÃ TỈNH (Không nhập) | M2: TỈNH THÀNH | N2: MÃ XÃ/PHƯỜNG (Không nhập) | O2: XÃ/PHƯỜNG | P2: ĐỊA CHỈ HIỆN TẠI (SỐ NHÀ, ẤP...)
A3: 123456 | B3: Lê Hoàng Nam | C3: =IFERROR(INDEX('Tham chiếu'!$W:$W,MATCH(D3,'Tham chiếu'!$Z:$Z,0)),"") -> 17.04.01.01.00.00.00 | D3: QK7/fBB5/PTM/BTH/ | E3: Chiến sĩ | F3: =IFERROR(INDEX('Tham chiếu'!$A:$A,MATCH(G3,'Tham chiếu'!$B:$B,0)),"") -> RANK003 | G3: Hạ sĩ | H3: 36838 | I3: Nam | J3: 79203003456 | K3: Phường Trảng Bàng, Tây Ninh | L3: =IFERROR(INDEX('Tham chiếu'!$N:$N,MATCH(M3,'Tham chiếu'!$O:$O,0)),"") -> 703 | M3: Lâm Đồng | N3: =IFERROR(INDEX('Tham chiếu'!$Q:$Q,MATCH(O3,'Tham chiếu'!$R:$R,0)),"") -> 70301001 | O3: Phường Xuân Hương - Đà Lạt | P3: 78 Trần Hưng Đạo | Q3: Kinh | R3: HSQ-CS | S3: Kinh | T3: =IFERROR(INDEX('Tham chiếu'!$K:$K,MATCH(U3,'Tham chiếu'!$L:$L,0)),"") -> MAR001 | U3: Độc thân | V3: 9/12 | W3: Điện dân dụng | X3: Sơ cấp | Y3: B | Z3: Loại 2 | AA3: 172 | AB3: 68 | AC3: 122/80 | AD3: 44245 | AE3: 45575 | AF3: 42455 | AG3: 123456.jpg
C4: =IFERROR(INDEX('Tham chiếu'!$W:$W,MATCH(D4,'Tham chiếu'!$Z:$Z,0)),"") | F4: =IFERROR(INDEX('Tham chiếu'!$A:$A,MATCH(#REF!,'Tham chiếu'!$B:$B,0)),"") | L4: =IFERROR(INDEX('Tham chiếu'!$N:$N,MATCH(M4,'Tham chiếu'!$O:$O,0)),"") | N4: =IFERROR(INDEX('Tham chiếu'!$Q:$Q,MATCH(O4,'Tham chiếu'!$R:$R,0)),"") | T4: =IFERROR(INDEX('Tham chiếu'!$K:$K,MATCH(U4,'Tham chiếu'!$L:$L,0)),"")
C5: =IFERROR(INDEX('Tham chiếu'!$W:$W,MATCH(D5,'Tham chiếu'!$Z:$Z,0)),"") | F5: =IFERROR(INDEX('Tham chiếu'!$A:$A,MATCH(#REF!,'Tham chiếu'!$B:$B,0)),"") | L5: =IFERROR(INDEX('Tham chiếu'!$N:$N,MATCH(M5,'Tham chiếu'!$O:$O,0)),"") | N5: =IFERROR(INDEX('Tham chiếu'!$Q:$Q,MATCH(O5,'Tham chiếu'!$R:$R,0)),"") | T5: =IFERROR(INDEX('Tham chiếu'!$K:$K,MATCH(U5,'Tham chiếu'!$L:$L,0)),"")
C6: =IFERROR(INDEX('Tham chiếu'!$W:$W,MATCH(D6,'Tham chiếu'!$Z:$Z,0)),"") | F6: =IFERROR(INDEX('Tham chiếu'!$A:$A,MATCH(#REF!,'Tham chiếu'!$B:$B,0)),"") | L6: =IFERROR(INDEX('Tham chiếu'!$N:$N,MATCH(M6,'Tham chiếu'!$O:$O,0)),"") | N6: =IFERROR(INDEX('Tham chiếu'!$Q:$Q,MATCH(O6,'Tham chiếu'!$R:$R,0)),"") | T6: =IFERROR(INDEX('Tham chiếu'!$K:$K,MATCH(U6,'Tham chiếu'!$L:$L,0)),"")
C7: =IFERROR(INDEX('Tham chiếu'!$W:$W,MATCH(D7,'Tham chiếu'!$Z:$Z,0)),"") | F7: =IFERROR(INDEX('Tham chiếu'!$A:$A,MATCH(#REF!,'Tham chiếu'!$B:$B,0)),"") | L7: =IFERROR(INDEX('Tham chiếu'!$N:$N,MATCH(M7,'Tham chiếu'!$O:$O,0)),"") | N7: =IFERROR(INDEX('Tham chiếu'!$Q:$Q,MATCH(O7,'Tham chiếu'!$R:$R,0)),"") | T7: =IFERROR(INDEX('Tham chiếu'!$K:$K,MATCH(U7,'Tham chiếu'!$L:$L,0)),"")
C8: =IFERROR(INDEX('Tham chiếu'!$W:$W,MATCH(D8,'Tham chiếu'!$Z:$Z,0)),"") | F8: =IFERROR(INDEX('Tham chiếu'!$A:$A,MATCH(#REF!,'Tham chiếu'!$B:$B,0)),"") | L8: =IFERROR(INDEX('Tham chiếu'!$N:$N,MATCH(M8,'Tham chiếu'!$O:$O,0)),"") | N8: =IFERROR(INDEX('Tham chiếu'!$Q:$Q,MATCH(O8,'Tham chiếu'!$R:$R,0)),"") | T8: =IFERROR(INDEX('Tham chiếu'!$K:$K,MATCH(U8,'Tham chiếu'!$L:$L,0)),"")
C9: =IFERROR(INDEX('Tham chiếu'!$W:$W,MATCH(D9,'Tham chiếu'!$Z:$Z,0)),"") | F9: =IFERROR(INDEX('Tham chiếu'!$A:$A,MATCH(#REF!,'Tham chiếu'!$B:$B,0)),"") | L9: =IFERROR(INDEX('Tham chiếu'!$N:$N,MATCH(M9,'Tham chiếu'!$O:$O,0)),"") | N9: =IFERROR(INDEX('Tham chiếu'!$Q:$Q,MATCH(O9,'Tham chiếu'!$R:$R,0)),"") | T9: =IFERROR(INDEX('Tham chiếu'!$K:$K,MATCH(U9,'Tham chiếu'!$L:$L,0)),"")
C10: =IFERROR(INDEX('Tham chiếu'!$W:$W,MATCH(D10,'Tham chiếu'!$Z:$Z,0)),"") | F10: =IFERROR(INDEX('Tham chiếu'!$A:$A,MATCH(#REF!,'Tham chiếu'!$B:$B,0)),"") | L10: =IFERROR(INDEX('Tham chiếu'!$N:$N,MATCH(M10,'Tham chiếu'!$O:$O,0)),"") | N10: =IFERROR(INDEX('Tham chiếu'!$Q:$Q,MATCH(O10,'Tham chiếu'!$R:$R,0)),"") | T10: =IFERROR(INDEX('Tham chiếu'!$K:$K,MATCH(U10,'Tham chiếu'!$L:$L,0)),"")
C11: =IFERROR(INDEX('Tham chiếu'!$W:$W,MATCH(D11,'Tham chiếu'!$Z:$Z,0)),"") | F11: =IFERROR(INDEX('Tham chiếu'!$A:$A,MATCH(#REF!,'Tham chiếu'!$B:$B,0)),"") | L11: =IFERROR(INDEX('Tham chiếu'!$N:$N,MATCH(M11,'Tham chiếu'!$O:$O,0)),"") | N11: =IFERROR(INDEX('Tham chiếu'!$Q:$Q,MATCH(O11,'Tham chiếu'!$R:$R,0)),"") | T11: =IFERROR(INDEX('Tham chiếu'!$K:$K,MATCH(U11,'Tham chiếu'!$L:$L,0)),"")
C12: =IFERROR(INDEX('Tham chiếu'!$W:$W,MATCH(D12,'Tham chiếu'!$Z:$Z,0)),"") | F12: =IFERROR(INDEX('Tham chiếu'!$A:$A,MATCH(#REF!,'Tham chiếu'!$B:$B,0)),"") | L12: =IFERROR(INDEX('Tham chiếu'!$N:$N,MATCH(M12,'Tham chiếu'!$O:$O,0)),"") | N12: =IFERROR(INDEX('Tham chiếu'!$Q:$Q,MATCH(O12,'Tham chiếu'!$R:$R,0)),"") | T12: =IFERROR(INDEX('Tham chiếu'!$K:$K,MATCH(U12,'Tham chiếu'!$L:$L,0)),"")
C13: =IFERROR(INDEX('Tham chiếu'!$W:$W,MATCH(D13,'Tham chiếu'!$Z:$Z,0)),"") | F13: =IFERROR(INDEX('Tham chiếu'!$A:$A,MATCH(#REF!,'Tham chiếu'!$B:$B,0)),"") | L13: =IFERROR(INDEX('Tham chiếu'!$N:$N,MATCH(M13,'Tham chiếu'!$O:$O,0)),"") | N13: =IFERROR(INDEX('Tham chiếu'!$Q:$Q,MATCH(O13,'Tham chiếu'!$R:$R,0)),"") | T13: =IFERROR(INDEX('Tham chiếu'!$K:$K,MATCH(U13,'Tham chiếu'!$L:$L,0)),"")
C14: =IFERROR(INDEX('Tham chiếu'!$W:$W,MATCH(D14,'Tham chiếu'!$Z:$Z,0)),"") | F14: =IFERROR(INDEX('Tham chiếu'!$A:$A,MATCH(#REF!,'Tham chiếu'!$B:$B,0)),"") | L14: =IFERROR(INDEX('Tham chiếu'!$N:$N,MATCH(M14,'Tham chiếu'!$O:$O,0)),"") | N14: =IFERROR(INDEX('Tham chiếu'!$Q:$Q,MATCH(O14,'Tham chiếu'!$R:$R,0)),"") | T14: =IFERROR(INDEX('Tham chiếu'!$K:$K,MATCH(U14,'Tham chiếu'!$L:$L,0)),"")
C15: =IFERROR(INDEX('Tham chiếu'!$W:$W,MATCH(D15,'Tham chiếu'!$Z:$Z,0)),"") | F15: =IFERROR(INDEX('Tham chiếu'!$A:$A,MATCH(#REF!,'Tham chiếu'!$B:$B,0)),"") | L15: =IFERROR(INDEX('Tham chiếu'!$N:$N,MATCH(M15,'Tham chiếu'!$O:$O,0)),"") | N15: =IFERROR(INDEX('Tham chiếu'!$Q:$Q,MATCH(O15,'Tham chiếu'!$R:$R,0)),"") | T15: =IFERROR(INDEX('Tham chiếu'!$K:$K,MATCH(U15,'Tham chiếu'!$L:$L,0)),"")
... C1081: =IFERROR(INDEX('Tham chiếu'!$W:$W,MATCH(D1081,'Tham chiếu'!$Z:$Z,0)),"") | F1081: =IFERROR(INDEX('Tham chiếu'!$A:$A,MATCH(#REF!,'Tham chiếu'!$B:$B,0)),"") | L1081: =IFERROR(INDEX('Tham chiếu'!$N:$N,MATCH(M1081,'Tham chiếu'!$O:$O,0)),"") | N1081: =IFERROR(INDEX('Tham chiếu'!$Q:$Q,MATCH(O1081,'Tham chiếu'!$R:$R,0)),"") | T1081: =IFERROR(INDEX('Tham chiếu'!$K:$K,MATCH(U1081,'Tham chiếu'!$L:$L,0)),"")
C1082: =IFERROR(INDEX('Tham chiếu'!$W:$W,MATCH(D1082,'Tham chiếu'!$Z:$Z,0)),"") | T1082: =IFERROR(INDEX('Tham chiếu'!$K:$K,MATCH(U1082,'Tham chiếu'!$L:$L,0)),"")

Sheet Quá trình công tác
A1: MÃ QUÂN NHÂN | B1: THỜI GIAN | D1: CHỨC VỤ, ĐƠN VỊ, BINH CHỦNG, CHIẾN TRƯỜNG (Ghi rõ đơn vị từ b,c,d,e,f… số QĐ, ngày QĐ)) | E1: MÃ CẤP BẬC (Không nhập) | F1: CẤP BẬC | G1: CHỨC VỤ ĐẢNG ĐOÀN THỂ
B2: TỪ | C2: ĐẾN
A3: 123456 | B3: 43876 | C3: 44561 | D3: Đại đội 1 | F3: Binh nhất | G3: Tiểu đội trưởng
A4: 123456 | B4: 44561 | C4: Hiện nay | D4: Đại đội 1 | E4: =IFERROR(INDEX('Tham chiếu'!$A:$A,MATCH(F4,'Tham chiếu'!$B:$B,0)),"") -> RANK004 | F4: Trung sĩ | G4: Tiểu đội trưởng
E5: =IFERROR(INDEX('Tham chiếu'!$A:$A,MATCH(F5,'Tham chiếu'!$B:$B,0)),"")
E6: =IFERROR(INDEX('Tham chiếu'!$A:$A,MATCH(F6,'Tham chiếu'!$B:$B,0)),"")
E7: =IFERROR(INDEX('Tham chiếu'!$A:$A,MATCH(F7,'Tham chiếu'!$B:$B,0)),"")
E8: =IFERROR(INDEX('Tham chiếu'!$A:$A,MATCH(F8,'Tham chiếu'!$B:$B,0)),"")
E9: =IFERROR(INDEX('Tham chiếu'!$A:$A,MATCH(F9,'Tham chiếu'!$B:$B,0)),"")
E10: =IFERROR(INDEX('Tham chiếu'!$A:$A,MATCH(F10,'Tham chiếu'!$B:$B,0)),"")
E11: =IFERROR(INDEX('Tham chiếu'!$A:$A,MATCH(F11,'Tham chiếu'!$B:$B,0)),"")
E12: =IFERROR(INDEX('Tham chiếu'!$A:$A,MATCH(F12,'Tham chiếu'!$B:$B,0)),"")
E13: =IFERROR(INDEX('Tham chiếu'!$A:$A,MATCH(F13,'Tham chiếu'!$B:$B,0)),"")
E14: =IFERROR(INDEX('Tham chiếu'!$A:$A,MATCH(F14,'Tham chiếu'!$B:$B,0)),"")
E15: =IFERROR(INDEX('Tham chiếu'!$A:$A,MATCH(F15,'Tham chiếu'!$B:$B,0)),"")
E16: =IFERROR(INDEX('Tham chiếu'!$A:$A,MATCH(F16,'Tham chiếu'!$B:$B,0)),"")
... E2429: =IFERROR(INDEX('Tham chiếu'!$A:$A,MATCH(F2429,'Tham chiếu'!$B:$B,0)),"")

Sheet Quá trình đào tạo
A1: MÃ QUÂN NHÂN | B1: TÊN TRƯỜNG | C1: NGÀNH HỌC HOẶC TÊN LỚP HỌC | D1: THỜI GIAN HỌC | F1: HÌNH THỨC | G1: BẰNG, CHỨNG CHỈ
D2: TỪ | E2: ĐẾN
A3: 123456 | B3: Trường Sĩ quan Lục quân 2 | C3: Chỉ huy Tham mưu Lục quân | D3: 43344 | E3: 44377 | F3: Bồi dưỡng | G3: Bằng Cử nhân Quân sự
A4: 123456 | B4: Trường Quân sự Quân khu 7 | C4: Bồi dưỡng cán bộ trung đội | D4: 44377 | E4: Hiện nay | F4: Bồi dưỡng | G4: Bằng Cử nhân Quân sự

Sheet Thân nhân
A1: MÃ QUÂN NHÂN | B1: QUAN HỆ | C1: HỌ VÀ TÊN THÂN NHÂN | D1: NGÀY SINH | E1: NGHỀ NGHIỆP | F1: NƠI CÔNG TÁC | G1: SĐT | H1: ĐỊA CHỈ | I1: PHỤ THUỘC (1: có, 0: không)
A2: 123456 | B2: Cha | C2: Nguyễn Văn A | D2: 12/03/1970 | E2: Làm nông | F2: Tây Ninh | G2: 0980273645 | H2: 123 abc, Xã A, Tỉnh B | I2: 0
A3: 123456 | B3: Mẹ | C3: Trần Thị B | D3: 17/09/1973 | E3: Làm nông | F3: Tây Ninh | G3: 0980273646 | H3: 124 abc, Xã A, Tỉnh B | I3: 0
A4: 123456 | B4: Vợ | C4: Nguyễn Thị C | D4: 20/01/2000 | E4: Giáo viên | F4: Tây Ninh | G4: 0980273647 | H4: 125 abc, Xã A, Tỉnh B | I4: 0

Sheet Tham chiếu
A1: Cấp bậc | E1: Trạng thái | H1: Loại nghiệp vụ | K1: Tình trạng hôn nhân | N1: Tỉnh thành | Q1: Phường xã | U1: Giới tính | W1: Đơn vị | AC1: Sức khỏe | AE1: Phụ thuộc
A2: RANK001 | B2: Binh nhì | C2: Hạ sĩ quan - chiến sĩ | E2: ST001 | F2: Đang tại ngũ | H2: SQ | I2: Sĩ quan | K2: MAR001 | L2: Độc thân | N2: 101 | O2: Hà Nội | Q2: 10101003 | R2: Phường Ba Đình | S2: 101 | U2: Nam | W2: Mã đơn vị* | X2: Tên đơn vị* | Y2: Tên viết tắt* | Z2: Link | AA2: Link name | AC2: Loại 1 | AE2: 1
A3: RANK002 | B3: Binh nhất | C3: Hạ sĩ quan - chiến sĩ | E3: ST002 | F3: Điều chuyển | H3: QNCN | I3: Quân nhân chuyên nghiệp | K3: MAR002 | L3: Đã kết hôn | N3: 103 | O3: Hải Phòng | Q3: 10101004 | R3: Phường Ngọc Hà | S3: 101 | U3: Nữ | W3: 17.00.00.00.00.00.00 | X3: Quân khu 7 | Y3: QK7 | Z3: QK7/ | AA3: Quân khu 7 | AC3: Loại 2 | AE3: 0
A4: RANK003 | B4: Hạ sĩ | C4: Hạ sĩ quan | E4: ST003 | F4: Nghỉ hưu | H4: HSQ-CS | I4: Hạ sĩ quan - Chiến sĩ | K4: MAR003 | L4: Ly hôn | N4: 109 | O4: Hưng Yên | Q4: 10101005 | R4: Phường Giảng Võ | S4: 101 | W4: 17.04.00.00.00.00.00 | X4: Sư đoàn Bộ binh 5 | Y4: fBB5 | Z4: QK7/fBB5/ | AA4: Quân khu 7,Sư đoàn Bộ binh 5 | AC4: Loại 3
A5: RANK004 | B5: Trung sĩ | C5: Hạ sĩ quan | E5: ST004 | F5: Xuất ngũ | H5: CNVCQP | I5: Công nhân viên chức quốc phòng | K5: MAR004 | L5: Góa | N5: 117 | O5: Ninh Bình | Q5: 10103014 | R5: Phường Hồng Hà | S5: 101 | W5: 17.04.01.00.00.00.00 | X5: Phòng Tham mưu | Y5: PTM | Z5: QK7/fBB5/PTM/ | AA5: Quân khu 7,Sư đoàn Bộ binh 5,Phòng Tham mưu | AC5: Loại 4
A6: RANK005 | B6: Thượng sĩ | C6: Hạ sĩ quan | N6: 201 | O6: Hà Giang | Q6: 10103028 | R6: Phường Tây Hồ | S6: 101 | W6: 17.04.01.01.00.00.00 | X6: Ban Tác huấn | Y6: BTH | Z6: QK7/fBB5/PTM/BTH/ | AA6: Quân khu 7,Sư đoàn Bộ binh 5,Phòng Tham mưu,Ban Tác huấn | AC6: Loại 5
A7: RANK006 | B7: Thiếu úy | C7: Sĩ quan | N7: 203 | O7: Cao Bằng | Q7: 10105001 | R7: Phường Hoàn Kiếm | S7: 101 | W7: 17.04.01.01.01.00.00 | X7: Tiểu đội Quản lý thao trường | Y7: aQLTT | Z7: QK7/fBB5/PTM/BTH/aQLTT/ | AA7: Quân khu 7,Sư đoàn Bộ binh 5,Phòng Tham mưu,Ban Tác huấn,Tiểu đội Quản lý thao trường | AC7: Loại 6
A8: RANK007 | B8: Trung úy | C8: Sĩ quan | N8: 205 | O8: Lào Cai | Q8: 10105002 | R8: Phường Cửa Nam | S8: 101 | W8: 17.04.01.02.00.00.00 | X8: Ban Trinh sát | Y8: BTS | Z8: QK7/fBB5/PTM/BTS/ | AA8: Quân khu 7,Sư đoàn Bộ binh 5,Phòng Tham mưu,Ban Trinh sát
A9: RANK008 | B9: Thượng úy | C9: Sĩ quan | N9: 209 | O9: Lạng Sơn | Q9: 10106039 | R9: Phường Long Biên | S9: 101 | W9: 17.04.01.03.00.00.00 | X9: Ban Quân lực | Y9: BQL | Z9: QK7/fBB5/PTM/BQL/ | AA9: Quân khu 7,Sư đoàn Bộ binh 5,Phòng Tham mưu,Ban Quân lực
A10: RANK009 | B10: Đại úy | C10: Sĩ quan | N10: 211 | O10: Tuyên Quang | Q10: 10106040 | R10: Phường Bồ Đề | S10: 101 | W10: 17.04.01.04.00.00.00 | X10: Ban Thông tin | Y10: BTT | Z10: QK7/fBB5/PTM/BTT/ | AA10: Quân khu 7,Sư đoàn Bộ binh 5,Phòng Tham mưu,Ban Thông tin
A11: RANK010 | B11: Thiếu tá | C11: Sĩ quan | N11: 215 | O11: Thái Nguyên | Q11: 10106041 | R11: Phường Việt Hưng | S11: 101 | W11: 17.04.01.04.01.00.00 | X11: Trạm Sửa chữa khí tài TT | Y11: TSCKTTT | Z11: QK7/fBB5/PTM/BTT/TSCKTTT/ | AA11: Quân khu 7,Sư đoàn Bộ binh 5,Phòng Tham mưu,Ban Thông tin,Trạm Sửa chữa khí tài TT
A12: RANK011 | B12: Trung tá | C12: Sĩ quan | N12: 217 | O12: Phú Thọ | Q12: 10106042 | R12: Phường Phúc Lợi | S12: 101 | W12: 17.04.01.05.00.00.00 | X12: Ban Cơ yếu | Y12: BCY | Z12: QK7/fBB5/PTM/BCY/ | AA12: Quân khu 7,Sư đoàn Bộ binh 5,Phòng Tham mưu,Ban Cơ yếu
A13: RANK012 | B13: Thượng tá | C13: Sĩ quan | N13: 223 | O13: Bắc Ninh | Q13: 10107006 | R13: Phường Hai Bà Trưng | S13: 101 | W13: 17.04.01.06.00.00.00 | X13: Ban Pháo binh | Y13: BPB | Z13: QK7/fBB5/PTM/BPB/ | AA13: Quân khu 7,Sư đoàn Bộ binh 5,Phòng Tham mưu,Ban Pháo binh
A14: RANK013 | B14: Đại tá | C14: Sĩ quan | N14: 225 | O14: Quảng Ninh | Q14: 10107007 | R14: Phường Vĩnh Tuy | S14: 101 | W14: 17.04.01.07.00.00.00 | X14: Ban Phòng không | Y14: BPK | Z14: QK7/fBB5/PTM/BPK/ | AA14: Quân khu 7,Sư đoàn Bộ binh 5,Phòng Tham mưu,Ban Phòng không
N15: 301 | O15: Điện Biên | Q15: 10107008 | R15: Phường Bạch Mai | S15: 101 | W15: 17.04.01.08.00.00.00 | X15: Ban Công binh | Y15: BCB | Z15: QK7/fBB5/PTM/BCB/ | AA15: Quân khu 7,Sư đoàn Bộ binh 5,Phòng Tham mưu,Ban Công binh
N16: 302 | O16: Lai Châu | Q16: 10108015 | R16: Phường Lĩnh Nam | S16: 101 | W16: 17.04.01.09.00.00.00 | X16: Ban Hành chính | Y16: BHC | Z16: QK7/fBB5/PTM/BHC/ | AA16: Quân khu 7,Sư đoàn Bộ binh 5,Phòng Tham mưu,Ban Hành chính
N17: 303 | O17: Sơn La | Q17: 10108016 | R17: Phường Hoàng Mai | S17: 101 | W17: 17.04.01.09.01.00.00 | X17: Tiểu đội Nấu ăn Cơ quan | Y17: aNACQ | Z17: QK7/fBB5/PTM/BHC/aNACQ/ | AA17: Quân khu 7,Sư đoàn Bộ binh 5,Phòng Tham mưu,Ban Hành chính,Tiểu đội Nấu ăn Cơ quan
N18: 401 | O18: Thanh Hóa | Q18: 10108017 | R18: Phường Vĩnh Hưng | S18: 101 | W18: 17.04.01.10.00.00.00 | X18: Đại đội 23 Vệ binh | Y18: c23 | Z18: QK7/fBB5/PTM/c23/ | AA18: Quân khu 7,Sư đoàn Bộ binh 5,Phòng Tham mưu,Đại đội 23 Vệ binh
N19: 403 | O19: Nghệ An | Q19: 10108018 | R19: Phường Tương Mai | S19: 101 | W19: 17.04.01.10.01.00.00 | X19: Tiểu đội Cối 60 | Y19: aCO60 | Z19: QK7/fBB5/PTM/c23/aCO60/ | AA19: Quân khu 7,Sư đoàn Bộ binh 5,Phòng Tham mưu,Đại đội 23 Vệ binh,Tiểu đội Cối 60
N20: 405 | O20: Hà Tĩnh | Q20: 10108019 | R20: Phường Định Công | S20: 101 | W20: 17.04.01.10.02.00.00 | X20: Tiểu đội Đại liên | Y20: aĐL | Z20: QK7/fBB5/PTM/c23/aĐL/ | AA20: Quân khu 7,Sư đoàn Bộ binh 5,Phòng Tham mưu,Đại đội 23 Vệ binh,Tiểu đội Đại liên
N21: 409 | O21: Quảng Trị | Q21: 10108021 | R21: Phường Yên Sở | S21: 101 | W21: 17.04.01.10.03.00.00 | X21: Trung đội 1 | Y21: b1 | Z21: QK7/fBB5/PTM/c23/b1/ | AA21: Quân khu 7,Sư đoàn Bộ binh 5,Phòng Tham mưu,Đại đội 23 Vệ binh,Trung đội 1
N22: 411 | O22: Huế | Q22: 10109009 | R22: Phường Đống Đa | S22: 101 | W22: 17.04.01.10.03.01.00 | X22: Tiểu đội 1 | Y22: a1 | Z22: QK7/fBB5/PTM/c23/b1/a1/ | AA22: Quân khu 7,Sư đoàn Bộ binh 5,Phòng Tham mưu,Đại đội 23 Vệ binh,Trung đội 1,Tiểu đội 1
N23: 501 | O23: Đà Nẵng | Q23: 10109010 | R23: Phường Kim Liên | S23: 101 | W23: 17.04.01.10.03.02.00 | X23: Tiểu đội 2 | Y23: a2 | Z23: QK7/fBB5/PTM/c23/b1/a2/ | AA23: Quân khu 7,Sư đoàn Bộ binh 5,Phòng Tham mưu,Đại đội 23 Vệ binh,Trung đội 1,Tiểu đội 2
N24: 505 | O24: Quảng Ngãi | Q24: 10109011 | R24: Phường Văn Miếu - Quốc Tử Giám | S24: 101 | W24: 17.04.01.10.03.03.00 | X24: Tiểu đội 3 | Y24: a3 | Z24: QK7/fBB5/PTM/c23/b1/a3/ | AA24: Quân khu 7,Sư đoàn Bộ binh 5,Phòng Tham mưu,Đại đội 23 Vệ binh,Trung đội 1,Tiểu đội 3
N25: 511 | O25: Khánh Hòa | Q25: 10109012 | R25: Phường Láng | S25: 101 | W25: 17.04.01.10.04.00.00 | X25: Trung đội 2 | Y25: b2 | Z25: QK7/fBB5/PTM/c23/b2/ | AA25: Quân khu 7,Sư đoàn Bộ binh 5,Phòng Tham mưu,Đại đội 23 Vệ binh,Trung đội 2
N26: 601 | O26: Kon Tum | Q26: 10109013 | R26: Phường Ô Chợ Dừa | S26: 101 | W26: 17.04.01.10.04.01.00 | X26: Tiểu đội 4 | Y26: a4 | Z26: QK7/fBB5/PTM/c23/b2/a4/ | AA26: Quân khu 7,Sư đoàn Bộ binh 5,Phòng Tham mưu,Đại đội 23 Vệ binh,Trung đội 2,Tiểu đội 4
... N37: 823 | O37: Cà Mau | Q37: 10115126 | R37: Xã Kim Anh | S37: 101 | W37: 17.04.03.00.00.00.00 | X37: Phòng Hậu cần - Kỹ thuật | Y37: PHCKT | Z37: QK7/fBB5/PHCKT/ | AA37: Quân khu 7,Sư đoàn Bộ binh 5,Phòng Hậu cần - Kỹ thuật
Q38: 10117113 | R38: Xã Thư Lâm | S38: 101 | W38: 17.04.03.01.00.00.00 | X38: Ban Tham mưu kế hoạch | Y38: BTMKH | Z38: QK7/fBB5/PHCKT/BTMKH/ | AA38: Quân khu 7,Sư đoàn Bộ binh 5,Phòng Hậu cần - Kỹ thuật,Ban Tham mưu kế hoạch
Q39: 10117114 | R39: Xã Đông Anh | S39: 101 | W39: 17.04.03.02.00.00.00 | X39: Ban Quân nhu | Y39: BQN | Z39: QK7/fBB5/PHCKT/BQN/ | AA39: Quân khu 7,Sư đoàn Bộ binh 5,Phòng Hậu cần - Kỹ thuật,Ban Quân nhu
Q40: 10117115 | R40: Xã Phúc Thịnh | S40: 101 | W40: 17.04.03.03.00.00.00 | X40: Ban Quân y | Y40: BQY | Z40: QK7/fBB5/PHCKT/BQY/ | AA40: Quân khu 7,Sư đoàn Bộ binh 5,Phòng Hậu cần - Kỹ thuật,Ban Quân y
Q41: 10117116 | R41: Xã Thiên Lộc | S41: 101 | W41: 17.04.03.04.00.00.00 | X41: Ban Doanh trại | Y41: BDT | Z41: QK7/fBB5/PHCKT/BDT/ | AA41: Quân khu 7,Sư đoàn Bộ binh 5,Phòng Hậu cần - Kỹ thuật,Ban Doanh trại
Q42: 10117117 | R42: Xã Vĩnh Thanh | S42: 101 | W42: 17.04.03.05.00.00.00 | X42: Ban Xăng dầu | Y42: BXD | Z42: QK7/fBB5/PHCKT/BXD/ | AA42: Quân khu 7,Sư đoàn Bộ binh 5,Phòng Hậu cần - Kỹ thuật,Ban Xăng dầu
Q43: 10119109 | R43: Xã Gia Lâm | S43: 101 | W43: 17.04.03.06.00.00.00 | X43: Ban Quân khí | Y43: BQK | Z43: QK7/fBB5/PHCKT/BQK/ | AA43: Quân khu 7,Sư đoàn Bộ binh 5,Phòng Hậu cần - Kỹ thuật,Ban Quân khí
Q44: 10119110 | R44: Xã Thuận An | S44: 101 | W44: 17.04.03.07.00.00.00 | X44: Ban Xe - máy | Y44: BXM | Z44: QK7/fBB5/PHCKT/BXM/ | AA44: Quân khu 7,Sư đoàn Bộ binh 5,Phòng Hậu cần - Kỹ thuật,Ban Xe - máy
Q45: 10119111 | R45: Xã Bát Tràng | S45: 101 | W45: 17.04.03.08.00.00.00 | X45: Trung đội 1: Kho Hậu cần | Y45: b1KhoHC | Z45: QK7/fBB5/PHCKT/b1KhoHC/ | AA45: Quân khu 7,Sư đoàn Bộ binh 5,Phòng Hậu cần - Kỹ thuật,Trung đội 1: Kho Hậu cần
Q46: 10119112 | R46: Xã Phù Đổng | S46: 101 | W46: 17.04.03.08.01.00.00 | X46: Tiểu đội 1: Kho, Bảo quản | Y46: a1KBQ | Z46: QK7/fBB5/PHCKT/b1KhoHC/a1KBQ/ | AA46: Quân khu 7,Sư đoàn Bộ binh 5,Phòng Hậu cần - Kỹ thuật,Trung đội 1: Kho Hậu cần,Tiểu đội 1: Kho, Bảo quản
Q47: 10123020 | R47: Phường Hoàng Liệt | S47: 101 | W47: 17.04.03.08.02.00.00 | X47: Tiểu đội 2: Vệ binh, bốc vác | Y47: a2VBBV | Z47: QK7/fBB5/PHCKT/b1KhoHC/a2VBBV/ | AA47: Quân khu 7,Sư đoàn Bộ binh 5,Phòng Hậu cần - Kỹ thuật,Trung đội 1: Kho Hậu cần,Tiểu đội 2: Vệ binh, bốc vác
Q48: 10123048 | R48: Xã Thanh Trì | S48: 101 | W48: 17.04.03.08.03.00.00 | X48: Tổ chế biến tập trung | Y48: TCBTT | Z48: QK7/fBB5/PHCKT/b1KhoHC/TCBTT/ | AA48: Quân khu 7,Sư đoàn Bộ binh 5,Phòng Hậu cần - Kỹ thuật,Trung đội 1: Kho Hậu cần,Tổ chế biến tập trung
Q49: 10123049 | R49: Xã Đại Thanh | S49: 101 | W49: 17.04.03.09.00.00.00 | X49: Đại đội Kho Kỹ thuật | Y49: cKhoKT | Z49: QK7/fBB5/PHCKT/cKhoKT/ | AA49: Quân khu 7,Sư đoàn Bộ binh 5,Phòng Hậu cần - Kỹ thuật,Đại đội Kho Kỹ thuật
... Q1269: 30307027 | R1269: Xã Mường É | S1269: 303 | W1269: 17.04.18.00.00.00.00 | X1269: Kho tăng | Y1269: Kho tng | Z1269: QK7/fBB5/Kho tng/ | AA1269: Quân khu 7,Sư đoàn Bộ binh 5,Kho tăng
...
